Traceback (most recent call last):
  File "/Users/maliabarker/Desktop/main/susie/venv/lib/python3.9/site-packages/jupyter_cache/executors/utils.py", line 58, in single_nb_execution
    executenb(
  File "/Users/maliabarker/Desktop/main/susie/venv/lib/python3.9/site-packages/nbclient/client.py", line 1314, in execute
    return NotebookClient(nb=nb, resources=resources, km=km, **kwargs).execute()
  File "/Users/maliabarker/Desktop/main/susie/venv/lib/python3.9/site-packages/jupyter_core/utils/__init__.py", line 168, in wrapped
    return loop.run_until_complete(inner)
  File "/usr/local/Cellar/python@3.9/3.9.7/Frameworks/Python.framework/Versions/3.9/lib/python3.9/asyncio/base_events.py", line 642, in run_until_complete
    return future.result()
  File "/Users/maliabarker/Desktop/main/susie/venv/lib/python3.9/site-packages/nbclient/client.py", line 709, in async_execute
    await self.async_execute_cell(
  File "/Users/maliabarker/Desktop/main/susie/venv/lib/python3.9/site-packages/nbclient/client.py", line 1062, in async_execute_cell
    await self._check_raise_for_error(cell, cell_index, exec_reply)
  File "/Users/maliabarker/Desktop/main/susie/venv/lib/python3.9/site-packages/nbclient/client.py", line 918, in _check_raise_for_error
    raise CellExecutionError.from_cell_and_msg(cell, exec_reply_content)
nbclient.exceptions.CellExecutionError: An error occurred while executing the following cell:
------------------
ephemeris_obj1 = Ephemeris(transit_times_obj1)
------------------


[0;31m---------------------------------------------------------------------------[0m
[0;31mNameError[0m                                 Traceback (most recent call last)
Cell [0;32mIn[2], line 1[0m
[0;32m----> 1[0m ephemeris_obj1 [38;5;241m=[39m Ephemeris([43mtransit_times_obj1[49m)

[0;31mNameError[0m: name 'transit_times_obj1' is not defined

