Traceback (most recent call last):
  File "/Users/maliabarker/Desktop/main/susie/venv/lib/python3.9/site-packages/jupyter_cache/executors/utils.py", line 58, in single_nb_execution
    executenb(
  File "/Users/maliabarker/Desktop/main/susie/venv/lib/python3.9/site-packages/nbclient/client.py", line 1314, in execute
    return NotebookClient(nb=nb, resources=resources, km=km, **kwargs).execute()
  File "/Users/maliabarker/Desktop/main/susie/venv/lib/python3.9/site-packages/jupyter_core/utils/__init__.py", line 168, in wrapped
    return loop.run_until_complete(inner)
  File "/usr/local/Cellar/python@3.9/3.9.7/Frameworks/Python.framework/Versions/3.9/lib/python3.9/asyncio/base_events.py", line 642, in run_until_complete
    return future.result()
  File "/Users/maliabarker/Desktop/main/susie/venv/lib/python3.9/site-packages/nbclient/client.py", line 709, in async_execute
    await self.async_execute_cell(
  File "/Users/maliabarker/Desktop/main/susie/venv/lib/python3.9/site-packages/nbclient/client.py", line 1062, in async_execute_cell
    await self._check_raise_for_error(cell, cell_index, exec_reply)
  File "/Users/maliabarker/Desktop/main/susie/venv/lib/python3.9/site-packages/nbclient/client.py", line 918, in _check_raise_for_error
    raise CellExecutionError.from_cell_and_msg(cell, exec_reply_content)
nbclient.exceptions.CellExecutionError: An error occurred while executing the following cell:
------------------
# STEP 1: Upload data
filepath = "./WASP12b_transit_ephemeris.csv" # IMPORTANT: Change to your own filepath
# filepath = "ENTER YOUR FILEPATH HERE"
data = np.genfromtxt(filepath, delimiter=',', names=True)
# STEP 2: Break data up into epochs, mid transit times, and error
epochs = data["epoch"]
mid_transit_times = data["transit_time"]
mid_transit_times_err = data["sigma_transit_time"]
# STEP 2.5 (Optional): Make sure the epochs are integers and not floats
epochs = epochs.astype('int')
------------------


[0;31m---------------------------------------------------------------------------[0m
[0;31mNameError[0m                                 Traceback (most recent call last)
Cell [0;32mIn[1], line 4[0m
[1;32m      2[0m filepath [38;5;241m=[39m [38;5;124m"[39m[38;5;124m./WASP12b_transit_ephemeris.csv[39m[38;5;124m"[39m [38;5;66;03m# IMPORTANT: Change to your own filepath[39;00m
[1;32m      3[0m [38;5;66;03m# filepath = "ENTER YOUR FILEPATH HERE"[39;00m
[0;32m----> 4[0m data [38;5;241m=[39m [43mnp[49m[38;5;241m.[39mgenfromtxt(filepath, delimiter[38;5;241m=[39m[38;5;124m'[39m[38;5;124m,[39m[38;5;124m'[39m, names[38;5;241m=[39m[38;5;28;01mTrue[39;00m)
[1;32m      5[0m [38;5;66;03m# STEP 2: Break data up into epochs, mid transit times, and error[39;00m
[1;32m      6[0m epochs [38;5;241m=[39m data[[38;5;124m"[39m[38;5;124mepoch[39m[38;5;124m"[39m]

[0;31mNameError[0m: name 'np' is not defined

